Workbook

Sheet P&L
A1: 2026 Farming Ventures — Costs & Profits
A2: Income Statement (P&L) • Season 2026
A3: Yellow = type here. White = auto-calculated. Crop sales pull from the Sales tab; every expense line pulls from the Expenses tab. Use the No Crop column for costs not tied to a crop (repairs, overhead). The TOTAL column counts every logged cost. Rename Crop 2 / Crop 3 below and pick the same names in the logs.
A5: ITEM | B5: Soybeans | C5: Corn | D5: Hay | E5: No Crop | F5: TOTAL (all crops)
A6: PRODUCTION
A7: Acres planted | B7: 26 | F7: =SUM(B7:E7) -> 26
A8: Total production (units harvested) | B8: 0 | F8: =SUM(B8:E8) -> 0
A10: REVENUE
A11: Crop sales (from Sales tab) | B11: =SUMIF(Sales!B3:B62,B5,Sales!F3:F62) -> 0 | C11: =SUMIF(Sales!B3:B62,C5,Sales!F3:F62) -> 0 | D11: =SUMIF(Sales!B3:B62,D5,Sales!F3:F62) -> 0 | E11: =SUMIF(Sales!B3:B62,E5,Sales!F3:F62) -> 0 | F11: =SUM(B11:E11) -> 0
A12: Government payments | F12: =SUM(B12:E12) -> 0
A13: Crop insurance proceeds | F13: =SUM(B13:E13) -> 0
A14: Other farm income | F14: =SUM(B14:E14) -> 0
A15: TOTAL REVENUE | B15: =SUM(B11:B14) -> 0 | C15: =SUM(C11:C14) -> 0 | D15: =SUM(D11:D14) -> 0 | E15: =SUM(E11:E14) -> 0 | F15: =SUM(B15:E15) -> 0
A17: OPERATING (VARIABLE) EXPENSES
A18: Seed | B18: =SUMIFS(Expenses!E3:E82,Expenses!C3:C82,A18,Expenses!B3:B82,B5) -> 2025 | C18: =SUMIFS(Expenses!E3:E82,Expenses!C3:C82,A18,Expenses!B3:B82,C5) -> 0 | D18: =SUMIFS(Expenses!E3:E82,Expenses!C3:C82,A18,Expenses!B3:B82,D5) -> 0 | E18: =SUMIFS(Expenses!E3:E82,Expenses!C3:C82,A18,Expenses!B3:B82,E5) -> 0 | F18: =SUMIF(Expenses!C3:C82,A18,Expenses!E3:E82) -> 2025
A19: Fertilizer & lime | B19: =SUMIFS(Expenses!E3:E82,Expenses!C3:C82,A19,Expenses!B3:B82,B5) -> 0 | C19: =SUMIFS(Expenses!E3:E82,Expenses!C3:C82,A19,Expenses!B3:B82,C5) -> 0 | D19: =SUMIFS(Expenses!E3:E82,Expenses!C3:C82,A19,Expenses!B3:B82,D5) -> 0 | E19: =SUMIFS(Expenses!E3:E82,Expenses!C3:C82,A19,Expenses!B3:B82,E5) -> 0 | F19: =SUMIF(Expenses!C3:C82,A19,Expenses!E3:E82) -> 0
A20: Chemicals (herbicide / pesticide) | B20: =SUMIFS(Expenses!E3:E82,Expenses!C3:C82,A20,Expenses!B3:B82,B5) -> 0 | C20: =SUMIFS(Expenses!E3:E82,Expenses!C3:C82,A20,Expenses!B3:B82,C5) -> 0 | D20: =SUMIFS(Expenses!E3:E82,Expenses!C3:C82,A20,Expenses!B3:B82,D5) -> 0 | E20: =SUMIFS(Expenses!E3:E82,Expenses!C3:C82,A20,Expenses!B3:B82,E5) -> 0 | F20: =SUMIF(Expenses!C3:C82,A20,Expenses!E3:E82) -> 0
A21: Crop insurance premiums | B21: =SUMIFS(Expenses!E3:E82,Expenses!C3:C82,A21,Expenses!B3:B82,B5) -> 0 | C21: =SUMIFS(Expenses!E3:E82,Expenses!C3:C82,A21,Expenses!B3:B82,C5) -> 0 | D21: =SUMIFS(Expenses!E3:E82,Expenses!C3:C82,A21,Expenses!B3:B82,D5) -> 0 | E21: =SUMIFS(Expenses!E3:E82,Expenses!C3:C82,A21,Expenses!B3:B82,E5) -> 0 | F21: =SUMIF(Expenses!C3:C82,A21,Expenses!E3:E82) -> 0
A22: Fuel & oil | B22: =SUMIFS(Expenses!E3:E82,Expenses!C3:C82,A22,Expenses!B3:B82,B5) -> 0 | C22: =SUMIFS(Expenses!E3:E82,Expenses!C3:C82,A22,Expenses!B3:B82,C5) -> 0 | D22: =SUMIFS(Expenses!E3:E82,Expenses!C3:C82,A22,Expenses!B3:B82,D5) -> 0 | E22: =SUMIFS(Expenses!E3:E82,Expenses!C3:C82,A22,Expenses!B3:B82,E5) -> 0 | F22: =SUMIF(Expenses!C3:C82,A22,Expenses!E3:E82) -> 0
A23: Custom hire / machine work | B23: =SUMIFS(Expenses!E3:E82,Expenses!C3:C82,A23,Expenses!B3:B82,B5) -> 0 | C23: =SUMIFS(Expenses!E3:E82,Expenses!C3:C82,A23,Expenses!B3:B82,C5) -> 0 | D23: =SUMIFS(Expenses!E3:E82,Expenses!C3:C82,A23,Expenses!B3:B82,D5) -> 0 | E23: =SUMIFS(Expenses!E3:E82,Expenses!C3:C82,A23,Expenses!B3:B82,E5) -> 0 | F23: =SUMIF(Expenses!C3:C82,A23,Expenses!E3:E82) -> 0
A24: Repairs & maintenance | B24: =SUMIFS(Expenses!E3:E82,Expenses!C3:C82,A24,Expenses!B3:B82,B5) -> 0 | C24: =SUMIFS(Expenses!E3:E82,Expenses!C3:C82,A24,Expenses!B3:B82,C5) -> 0 | D24: =SUMIFS(Expenses!E3:E82,Expenses!C3:C82,A24,Expenses!B3:B82,D5) -> 0 | E24: =SUMIFS(Expenses!E3:E82,Expenses!C3:C82,A24,Expenses!B3:B82,E5) -> 15 | F24: =SUMIF(Expenses!C3:C82,A24,Expenses!E3:E82) -> 15
A25: Drying & storage | B25: =SUMIFS(Expenses!E3:E82,Expenses!C3:C82,A25,Expenses!B3:B82,B5) -> 0 | C25: =SUMIFS(Expenses!E3:E82,Expenses!C3:C82,A25,Expenses!B3:B82,C5) -> 0 | D25: =SUMIFS(Expenses!E3:E82,Expenses!C3:C82,A25,Expenses!B3:B82,D5) -> 0 | E25: =SUMIFS(Expenses!E3:E82,Expenses!C3:C82,A25,Expenses!B3:B82,E5) -> 0 | F25: =SUMIF(Expenses!C3:C82,A25,Expenses!E3:E82) -> 0
A26: Hauling / trucking | B26: =SUMIFS(Expenses!E3:E82,Expenses!C3:C82,A26,Expenses!B3:B82,B5) -> 0 | C26: =SUMIFS(Expenses!E3:E82,Expenses!C3:C82,A26,Expenses!B3:B82,C5) -> 0 | D26: =SUMIFS(Expenses!E3:E82,Expenses!C3:C82,A26,Expenses!B3:B82,D5) -> 0 | E26: =SUMIFS(Expenses!E3:E82,Expenses!C3:C82,A26,Expenses!B3:B82,E5) -> 0 | F26: =SUMIF(Expenses!C3:C82,A26,Expenses!E3:E82) -> 0
A27: Hired labor | B27: =SUMIFS(Expenses!E3:E82,Expenses!C3:C82,A27,Expenses!B3:B82,B5) -> 0 | C27: =SUMIFS(Expenses!E3:E82,Expenses!C3:C82,A27,Expenses!B3:B82,C5) -> 0 | D27: =SUMIFS(Expenses!E3:E82,Expenses!C3:C82,A27,Expenses!B3:B82,D5) -> 0 | E27: =SUMIFS(Expenses!E3:E82,Expenses!C3:C82,A27,Expenses!B3:B82,E5) -> 0 | F27: =SUMIF(Expenses!C3:C82,A27,Expenses!E3:E82) -> 0
A28: Land rent / lease | B28: =SUMIFS(Expenses!E3:E82,Expenses!C3:C82,A28,Expenses!B3:B82,B5) -> 0 | C28: =SUMIFS(Expenses!E3:E82,Expenses!C3:C82,A28,Expenses!B3:B82,C5) -> 0 | D28: =SUMIFS(Expenses!E3:E82,Expenses!C3:C82,A28,Expenses!B3:B82,D5) -> 0 | E28: =SUMIFS(Expenses!E3:E82,Expenses!C3:C82,A28,Expenses!B3:B82,E5) -> 0 | F28: =SUMIF(Expenses!C3:C82,A28,Expenses!E3:E82) -> 0
A29: Operating loan interest | B29: =SUMIFS(Expenses!E3:E82,Expenses!C3:C82,A29,Expenses!B3:B82,B5) -> 0 | C29: =SUMIFS(Expenses!E3:E82,Expenses!C3:C82,A29,Expenses!B3:B82,C5) -> 0 | D29: =SUMIFS(Expenses!E3:E82,Expenses!C3:C82,A29,Expenses!B3:B82,D5) -> 0 | E29: =SUMIFS(Expenses!E3:E82,Expenses!C3:C82,A29,Expenses!B3:B82,E5) -> 0 | F29: =SUMIF(Expenses!C3:C82,A29,Expenses!E3:E82) -> 0
A30: Supplies & miscellaneous | B30: =SUMIFS(Expenses!E3:E82,Expenses!C3:C82,A30,Expenses!B3:B82,B5) -> 0 | C30: =SUMIFS(Expenses!E3:E82,Expenses!C3:C82,A30,Expenses!B3:B82,C5) -> 0 | D30: =SUMIFS(Expenses!E3:E82,Expenses!C3:C82,A30,Expenses!B3:B82,D5) -> 0 | E30: =SUMIFS(Expenses!E3:E82,Expenses!C3:C82,A30,Expenses!B3:B82,E5) -> 0 | F30: =SUMIF(Expenses!C3:C82,A30,Expenses!E3:E82) -> 0
A31: TOTAL OPERATING EXPENSES | B31: =SUM(B18:B30) -> 2025 | C31: =SUM(C18:C30) -> 0 | D31: =SUM(D18:D30) -> 0 | E31: =SUM(E18:E30) -> 15 | F31: =SUM(F18:F30) -> 2040
A33: GROSS MARGIN (Revenue − Operating) | B33: =B15-B31 -> -2025 | C33: =C15-C31 -> 0 | D33: =D15-D31 -> 0 | E33: =E15-E31 -> -15 | F33: =F15-F31 -> -2040
A35: FIXED / OVERHEAD EXPENSES
A36: Property / land taxes | B36: =SUMIFS(Expenses!E3:E82,Expenses!C3:C82,A36,Expenses!B3:B82,B5) -> 0 | C36: =SUMIFS(Expenses!E3:E82,Expenses!C3:C82,A36,Expenses!B3:B82,C5) -> 0 | D36: =SUMIFS(Expenses!E3:E82,Expenses!C3:C82,A36,Expenses!B3:B82,D5) -> 0 | E36: =SUMIFS(Expenses!E3:E82,Expenses!C3:C82,A36,Expenses!B3:B82,E5) -> 0 | F36: =SUMIF(Expenses!C3:C82,A36,Expenses!E3:E82) -> 0
A37: Farm & liability insurance | B37: =SUMIFS(Expenses!E3:E82,Expenses!C3:C82,A37,Expenses!B3:B82,B5) -> 0 | C37: =SUMIFS(Expenses!E3:E82,Expenses!C3:C82,A37,Expenses!B3:B82,C5) -> 0 | D37: =SUMIFS(Expenses!E3:E82,Expenses!C3:C82,A37,Expenses!B3:B82,D5) -> 0 | E37: =SUMIFS(Expenses!E3:E82,Expenses!C3:C82,A37,Expenses!B3:B82,E5) -> 0 | F37: =SUMIF(Expenses!C3:C82,A37,Expenses!E3:E82) -> 0
A38: Depreciation (equipment & buildings) | B38: =SUMIFS(Expenses!E3:E82,Expenses!C3:C82,A38,Expenses!B3:B82,B5) -> 0 | C38: =SUMIFS(Expenses!E3:E82,Expenses!C3:C82,A38,Expenses!B3:B82,C5) -> 0 | D38: =SUMIFS(Expenses!E3:E82,Expenses!C3:C82,A38,Expenses!B3:B82,D5) -> 0 | E38: =SUMIFS(Expenses!E3:E82,Expenses!C3:C82,A38,Expenses!B3:B82,E5) -> 0 | F38: =SUMIF(Expenses!C3:C82,A38,Expenses!E3:E82) -> 0
A39: Term loan interest | B39: =SUMIFS(Expenses!E3:E82,Expenses!C3:C82,A39,Expenses!B3:B82,B5) -> 0 | C39: =SUMIFS(Expenses!E3:E82,Expenses!C3:C82,A39,Expenses!B3:B82,C5) -> 0 | D39: =SUMIFS(Expenses!E3:E82,Expenses!C3:C82,A39,Expenses!B3:B82,D5) -> 0 | E39: =SUMIFS(Expenses!E3:E82,Expenses!C3:C82,A39,Expenses!B3:B82,E5) -> 0 | F39: =SUMIF(Expenses!C3:C82,A39,Expenses!E3:E82) -> 0
A40: Other overhead | B40: =SUMIFS(Expenses!E3:E82,Expenses!C3:C82,A40,Expenses!B3:B82,B5) -> 0 | C40: =SUMIFS(Expenses!E3:E82,Expenses!C3:C82,A40,Expenses!B3:B82,C5) -> 0 | D40: =SUMIFS(Expenses!E3:E82,Expenses!C3:C82,A40,Expenses!B3:B82,D5) -> 0 | E40: =SUMIFS(Expenses!E3:E82,Expenses!C3:C82,A40,Expenses!B3:B82,E5) -> 0 | F40: =SUMIF(Expenses!C3:C82,A40,Expenses!E3:E82) -> 0
A41: TOTAL FIXED EXPENSES | B41: =SUM(B36:B40) -> 0 | C41: =SUM(C36:C40) -> 0 | D41: =SUM(D36:D40) -> 0 | E41: =SUM(E36:E40) -> 0 | F41: =SUM(F36:F40) -> 0
A43: NET PROFIT / (LOSS) | B43: =B15-B31-B41 -> -2025 | C43: =C15-C31-C41 -> 0 | D43: =D15-D31-D41 -> 0 | E43: =E15-E31-E41 -> -15 | F43: =F15-F31-F41 -> -2040
A45: PER-ACRE METRICS
A46: Revenue per acre | B46: =IF(B7=0,0,B15/B7) -> 0 | C46: =IF(C7=0,0,C15/C7) -> 0 | D46: =IF(D7=0,0,D15/D7) -> 0 | E46: =IF(E7=0,0,E15/E7) -> 0 | F46: =IF(F7=0,0,F15/F7) -> 0
A47: Total cost per acre | B47: =IF(B7=0,0,(B31+B41)/B7) -> 77.884615 | C47: =IF(C7=0,0,(C31+C41)/C7) -> 0 | D47: =IF(D7=0,0,(D31+D41)/D7) -> 0 | E47: =IF(E7=0,0,(E31+E41)/E7) -> 0 | F47: =IF(F7=0,0,(F31+F41)/F7) -> 78.461538
...

Sheet Sales
A1: Sales Log — 2026 | H1: ▼ Crop list (do not delete)
A2: Date | B2: Crop | C2: Buyer / Market | D2: Quantity (units) | E2: Price / unit ($) | F2: Amount ($) | G2: Notes | H2: ='P&L'!B5 -> Soybeans
B3: Soybeans | F3: =D3*E3 -> 0 | H3: ='P&L'!C5 -> Corn
F4: =D4*E4 -> 0 | H4: ='P&L'!D5 -> Hay
F5: =D5*E5 -> 0 | H5: ='P&L'!E5 -> No Crop
F6: =D6*E6 -> 0
F7: =D7*E7 -> 0
F8: =D8*E8 -> 0
F9: =D9*E9 -> 0
F10: =D10*E10 -> 0
F11: =D11*E11 -> 0
F12: =D12*E12 -> 0
F13: =D13*E13 -> 0
F14: =D14*E14 -> 0
F15: =D15*E15 -> 0
F16: =D16*E16 -> 0
F17: =D17*E17 -> 0
... F62: =D62*E62 -> 0
C63: TOTAL SALES | F63: =SUM(F3:F62) -> 0

Sheet Expenses
A1: Expense Log — 2026 | G1: ▼ Crop list (do not delete)
A2: Date | B2: Crop | C2: Category | D2: Vendor | E2: Amount ($) | F2: Notes | G2: ='P&L'!B5 -> Soybeans
A3: 46179 | B3: Soybeans | C3: Seed | D3: Troy Crispen | E3: 900 | F3: Planted 06/04/26 Whiteside Road | G3: ='P&L'!C5 -> Corn
A4: 46179 | B4: Soybeans | C4: Seed | D4: Troy Crispen | E4: 1125 | F4: Planted 06/06/26 Straub Road | G4: ='P&L'!D5 -> Hay
A5: 46179 | B5: No Crop | C5: Repairs & maintenance | D5: Troy Crispen | E5: 15 | F5: Power Steering Hose | G5: ='P&L'!E5 -> No Crop
C83: TOTAL EXPENSES | E83: =SUM(E3:E82) -> 2040
A85: COST-CAPTURE CHECK
C86: Captured by the P&L expense lines | E86: ='P&L'!F31+'P&L'!F41 -> 2040
C87: Unmatched vs logged total — should be $0 | E87: =E83-E86 -> 0
A88: If “Unmatched” is not $0, a logged cost has a Category that is not one of the P&L expense lines, so the farm totals are not counting it — fix that row’s Category.

Sheet Assets & Depreciation
A1: Assets & Depreciation (straight-line)
A2: Annual depreciation = (Cost − Salvage) ÷ Useful life. Log the TOTAL below as a “Depreciation” expense in the Expenses tab.
A3: Item / Equipment | B3: Purchase date | C3: Cost ($) | D3: Salvage value ($) | E3: Useful life (yrs) | F3: Annual depreciation ($) | G3: Accumulated to date ($)
F4: =IF(E4=0,0,(C4-D4)/E4) -> 0
F5: =IF(E5=0,0,(C5-D5)/E5) -> 0
F6: =IF(E6=0,0,(C6-D6)/E6) -> 0
F7: =IF(E7=0,0,(C7-D7)/E7) -> 0
F8: =IF(E8=0,0,(C8-D8)/E8) -> 0
F9: =IF(E9=0,0,(C9-D9)/E9) -> 0
F10: =IF(E10=0,0,(C10-D10)/E10) -> 0
F11: =IF(E11=0,0,(C11-D11)/E11) -> 0
F12: =IF(E12=0,0,(C12-D12)/E12) -> 0
F13: =IF(E13=0,0,(C13-D13)/E13) -> 0
F14: =IF(E14=0,0,(C14-D14)/E14) -> 0
F15: =IF(E15=0,0,(C15-D15)/E15) -> 0
... F23: =IF(E23=0,0,(C23-D23)/E23) -> 0
A24: TOTAL ANNUAL DEPRECIATION | F24: =SUM(F4:F23) -> 0 | G24: =SUM(G4:G23) -> 0

Sheet Summary
A1: 2026 Farm Summary — Dashboard
A2: Live snapshot pulled from the P&L tab.
A4: WHOLE-FARM TOTALS
A5: Total revenue | B5: ='P&L'!F15 -> 0
A6: Total operating expenses | B6: ='P&L'!F31 -> 2040
A7: Total fixed expenses | B7: ='P&L'!F41 -> 0
A8: Net profit / (loss) | B8: ='P&L'!F43 -> -2040
A9: Profit margin | B9: =IF('P&L'!F15=0,0,'P&L'!F43/'P&L'!F15) -> 0
A11: PRODUCTIVITY
A12: Total acres planted | B12: ='P&L'!F7 -> 26
A13: Revenue per acre | B13: ='P&L'!F46 -> 0
A14: Total cost per acre | B14: ='P&L'!F47 -> 78.461538
A15: Profit per acre | B15: ='P&L'!F48 -> -78.461538
A17: BY CROP
A18: Crop | B18: Revenue | C18: Total cost | D18: Net profit | E18: Profit / acre
A19: ='P&L'!B5 -> Soybeans | B19: ='P&L'!B15 -> 0 | C19: ='P&L'!B31+'P&L'!B41 -> 2025 | D19: ='P&L'!B43 -> -2025 | E19: ='P&L'!B48 -> -77.884615
A20: ='P&L'!C5 -> Corn | B20: ='P&L'!C15 -> 0 | C20: ='P&L'!C31+'P&L'!C41 -> 0 | D20: ='P&L'!C43 -> 0 | E20: ='P&L'!C48 -> 0
A21: ='P&L'!D5 -> Hay | B21: ='P&L'!D15 -> 0 | C21: ='P&L'!D31+'P&L'!D41 -> 0 | D21: ='P&L'!D43 -> 0 | E21: ='P&L'!D48 -> 0
A22: ='P&L'!E5 -> No Crop | B22: ='P&L'!E15 -> 0 | C22: ='P&L'!E31+'P&L'!E41 -> 15 | D22: ='P&L'!E43 -> -15 | E22: ='P&L'!E48 -> 0
